/var/spool/slurmd/job6718376/slurm_script: line 16: /m100_scratch/userexternal/gfiamen1/phd-ai/hpdl-env/etc/profile.d/conda.sh: No such file or directory

CommandNotFoundError: Your shell has not been properly configured to use 'conda activate'.
To initialize your shell, run

    $ conda init <SHELL_NAME>

Currently supported shells are:
  - bash
  - fish
  - tcsh
  - xonsh
  - zsh
  - powershell

See 'conda init --help' for more information and options.

IMPORTANT: You may need to close and restart your shell after running 'conda init'.


/var/spool/slurmd/job6718376/slurm_script: line 22: cd: /m100_scratch/userexternal/gfiamen1/phd-ai/hpdl-env/hpdl: No such file or directory
WARNING:torch.distributed.run:
*****************************************
Setting OMP_NUM_THREADS environment variable for each process to be 1 in default, to avoid your system being overloaded, please further tune the variable for optimal performance in your application as needed. 
*****************************************
/cineca/prod/opt/libraries/cineca-ai/2.1.0/none/cineca-ai-conda-env-py3.8-cuda-openmpi-11.0/bin/python: can't open file 'code/ddp.py': [Errno 2] No such file or directory
/cineca/prod/opt/libraries/cineca-ai/2.1.0/none/cineca-ai-conda-env-py3.8-cuda-openmpi-11.0/bin/python: can't open file 'code/ddp.py': [Errno 2] No such file or directory
ERROR:torch.distributed.elastic.multiprocessing.api:failed (exitcode: 2) local_rank: 0 (pid: 11752) of binary: /cineca/prod/opt/libraries/cineca-ai/2.1.0/none/cineca-ai-conda-env-py3.8-cuda-openmpi-11.0/bin/python
Traceback (most recent call last):
  File "/cineca/prod/opt/libraries/cineca-ai/2.1.0/none/cineca-ai-conda-env-py3.8-cuda-openmpi-11.0/lib/python3.8/runpy.py", line 194, in _run_module_as_main
    return _run_code(code, main_globals, None,
  File "/cineca/prod/opt/libraries/cineca-ai/2.1.0/none/cineca-ai-conda-env-py3.8-cuda-openmpi-11.0/lib/python3.8/runpy.py", line 87, in _run_code
    exec(code, run_globals)
  File "/cineca/prod/opt/libraries/cineca-ai/2.1.0/none/cineca-ai-conda-env-py3.8-cuda-openmpi-11.0/lib/python3.8/site-packages/torch/distributed/launch.py", line 193, in <module>
    main()
  File "/cineca/prod/opt/libraries/cineca-ai/2.1.0/none/cineca-ai-conda-env-py3.8-cuda-openmpi-11.0/lib/python3.8/site-packages/torch/distributed/launch.py", line 189, in main
    launch(args)
  File "/cineca/prod/opt/libraries/cineca-ai/2.1.0/none/cineca-ai-conda-env-py3.8-cuda-openmpi-11.0/lib/python3.8/site-packages/torch/distributed/launch.py", line 174, in launch
    run(args)
  File "/cineca/prod/opt/libraries/cineca-ai/2.1.0/none/cineca-ai-conda-env-py3.8-cuda-openmpi-11.0/lib/python3.8/site-packages/torch/distributed/run.py", line 710, in run
    elastic_launch(
  File "/cineca/prod/opt/libraries/cineca-ai/2.1.0/none/cineca-ai-conda-env-py3.8-cuda-openmpi-11.0/lib/python3.8/site-packages/torch/distributed/launcher/api.py", line 131, in __call__
    return launch_agent(self._config, self._entrypoint, list(args))
  File "/cineca/prod/opt/libraries/cineca-ai/2.1.0/none/cineca-ai-conda-env-py3.8-cuda-openmpi-11.0/lib/python3.8/site-packages/torch/distributed/launcher/api.py", line 259, in launch_agent
    raise ChildFailedError(
torch.distributed.elastic.multiprocessing.errors.ChildFailedError: 
============================================================
code/ddp.py FAILED
------------------------------------------------------------
Failures:
[1]:
  time      : 2022-05-30_12:31:20
  host      : r248n14.m100.cineca.it
  rank      : 1 (local_rank: 1)
  exitcode  : 2 (pid: 11753)
  error_file: <N/A>
  traceback : To enable traceback see: https://pytorch.org/docs/stable/elastic/errors.html
------------------------------------------------------------
Root Cause (first observed failure):
[0]:
  time      : 2022-05-30_12:31:20
  host      : r248n14.m100.cineca.it
  rank      : 0 (local_rank: 0)
  exitcode  : 2 (pid: 11752)
  error_file: <N/A>
  traceback : To enable traceback see: https://pytorch.org/docs/stable/elastic/errors.html
============================================================
srun: error: r248n14: task 0: Exited with exit code 1
srun: launch/slurm: _step_signal: Terminating StepId=6718376.0

CommandNotFoundError: Your shell has not been properly configured to use 'conda deactivate'.
To initialize your shell, run

    $ conda init <SHELL_NAME>

Currently supported shells are:
  - bash
  - fish
  - tcsh
  - xonsh
  - zsh
  - powershell

See 'conda init --help' for more information and options.

IMPORTANT: You may need to close and restart your shell after running 'conda init'.


